$ python failcases.py

EE
======================================================================
ERROR: test_builtin_extension1 (__main__.UsingMockDatetimeFailTest)
datetime.nowをモックに置き換えようとするとエラーになる。
----------------------------------------------------------------------
Traceback (most recent call last):
  File "failcases.py", line 16, in test_builtin_extension1
    with mock.patch("datetime.datetime.now") as M:
  File "build/bdist.linux-i686/egg/mock.py", line 1348, in __enter__
    setattr(self.target, self.attribute, new_attr)
TypeError: can't set attributes of built-in/extension type 'datetime.datetime'

======================================================================
ERROR: test_builtin_extension2 (__main__.UsingMockDatetimeFailTest)
datetime.nowをモックに置き換えようとするとエラーになる。
----------------------------------------------------------------------
Traceback (most recent call last):
  File "failcases.py", line 28, in test_builtin_extension2
    with mock.patch("mydatetime.datetime.now") as M:
  File "build/bdist.linux-i686/egg/mock.py", line 1348, in __enter__
    setattr(self.target, self.attribute, new_attr)
TypeError: can't set attributes of built-in/extension type 'datetime.datetime'

----------------------------------------------------------------------
Ran 2 tests in 0.008s

FAILED (errors=2)


$ python failcases2.py

F
======================================================================
FAIL: test_import_timing (__main__.UsingMockDatetimeFailTest2)
インポートのタイミングによって結果が変わることを示す例。
----------------------------------------------------------------------
Traceback (most recent call last):
  File "failcases2.py", line 29, in test_import_timing
    self.assertEqual(mydatetime.now(), 10)
AssertionError: datetime.datetime(2012, 9, 6, 14, 6, 21, 736866) != 10

----------------------------------------------------------------------
Ran 1 test in 0.018s

FAILED (failures=1)


$ python failcases3.py

.
----------------------------------------------------------------------
Ran 1 test in 0.002s

OK
