単独でテストコードを実行するとOKになる。

$ python test_with_mock.py
..
----------------------------------------------------------------------
Ran 2 tests in 0.004s

OK


$ python test_with_mock2.py
.
----------------------------------------------------------------------
Ran 1 test in 0.001s

OK


ところが、両方一度に実行すると失敗する。

$ python -m unittest discover
FF.
======================================================================
FAIL: test (test_with_mock.UsingMockDatetimeTest)
----------------------------------------------------------------------
Traceback (most recent call last):
  File "/home/oyakata/srg.mocktool-usage/src/dt/usingmock/test_with_mock.py", line 14, in test
    self.assertEqual(self._callFUT(), 10)
AssertionError: datetime.datetime(2012, 9, 6, 11, 44, 18, 408965) != 10

======================================================================
FAIL: test2 (test_with_mock.UsingMockDatetimeTest)
----------------------------------------------------------------------
Traceback (most recent call last):
  File "/home/oyakata/srg.mocktool-usage/src/dt/usingmock/test_with_mock.py", line 20, in test2
    self.assertEqual(self._callFUT(), 10)
AssertionError: datetime.datetime(2012, 9, 6, 11, 44, 18, 409808) != 10

----------------------------------------------------------------------
Ran 3 tests in 0.003s

FAILED (failures=2)
